File: publications/Rheology of PAC solutions/FC/Data/Lab1_SINTEF_Petroleum/PAC4.csv
Data Series Information,,,,,,,,
Name:,,,Scatter study - HFC - PAC4 2nd batch - 1,,,,,
Sample:,,,"Dist. H2O + 4 g/L PAC, 2nd batch",,,,,
Operator:,,,Alex,,,,,
Remarks:,,,Bergen,,,,,
Number of Intervals:,,,3,,,,,
Application:,,,RHEOPLUS/32 V3.61 21006089-33024,,,,,
Device:,,,"MCR102 SN81115860; FW3.86; Slot(4,-1); Adj(69,0)d",,,,,
Measuring Date/Time:,,,08/07/2015; 18:53 PM,,,,,
Measuring System:,,,CC27-SN26350; d=0 mm,,,,,
Accessories:,,,TU1=C-PTD200-SN81077144,,,,,
,,,,,,,,
Calculating Constants:,,,,,,,,
- Csr [min/s]:,,,12.789.756,,,,,
- Css [Pa/mNm]:,,,18.841.121,,,,,
- Start Delay Time [s]:,,,7.361,,,,,
- Substance Density [rho]:,,,1,,,,,
- Measurement Type:,,,2,,,,,
- Axial Compliance [m/N]:,,,1.00E-06,,,,,
- Position [m]:,,,1.00E-06,,,,,
,,,,,,,,
Interval:,,,1,,,,,
Number of Data Points:,,,50,,,,,
,,,,,,,,
Time Setting:,,,50 Meas. Pts.,,,,,
,,,Meas. Pt. Duration 5 s,,,,,
Measuring Profile:,,,,,,,,
  Shear Rate,,,"d(gamma)/dt = 0.01 ... 1,200 1/s log",,,,,
,,,,,,,,
Meas. Pts.,Time,Shear Stress,Shear Rate,Viscosity,Speed,Torque,Status,Temperature
,[s],[Pa],[1/s],[Pa·s],[1/min],[µNm],[],[°C]
1,5,0.000359,0.01,0.0359,0.00782,0.019,"M- ,Dy_",21
2,10,0.000741,0.0127,0.0583,0.00993,0.0393,"M- ,Dy_",20.997
3,15,0.00135,0.0161,0.0839,0.0126,0.0717,Dy_accu,20.993
4,20,0.0021,0.0205,0.102,0.016,0.111,Dy_accu,20.989
5,25,0.00311,0.026,0.12,0.0203,0.165,Dy_accu,20.986
6,30,0.0045,0.033,0.137,0.0258,0.239,Dy_accu,20.987
7,35,0.00632,0.0419,0.151,0.0327,0.335,Dy_accu,20.987
8,40,0.00831,0.0532,0.156,0.0416,0.441,Dy_accu,20.989
9,45,0.0109,0.0675,0.162,0.0528,0.58,Dy_accu,20.993
10,50,0.0144,0.0857,0.167,0.067,0.762,Dy_accu,20.995
11,55,0.0186,0.109,0.171,0.0851,0.987,Dy_accu,20.997
12,60,0.0239,0.138,0.173,0.108,1.27,Dy_accu,21
13,65,0.0302,0.175,0.172,0.137,1.6,Dy_accu,21.002
14,70,0.0381,0.223,0.171,0.174,2.02,Dy_accu,21.004
15,75,0.0481,0.283,0.17,0.221,2.55,Dy_accu,21.006
16,80,0.0601,0.359,0.168,0.281,3.19,Dy_accu,21.003
17,85,0.075,0.456,0.165,0.356,3.98,Dy_accu,21
18,90,0.0949,0.578,0.164,0.452,5.04,Dy_accu,20.995
19,95,0.12,0.734,0.164,0.574,6.38,Dy_accu,20.99
20,100,0.152,0.932,0.163,0.729,8.05,Dy_accu,20.99
21,105,0.191,1.18,0.161,0.925,10.1,Dy_accu,20.992
22,110,0.241,1.5,0.16,1.17,12.8,Dy_accu,20.993
23,115,0.303,1.91,0.159,1.49,16.1,Dy_accu,20.995
24,120,0.378,2.42,0.156,1.89,20.1,Dy_accu,20.998
25,125,0.471,3.07,0.153,2.4,25,Dy_accu,21
26,130,0.586,3.9,0.15,3.05,31.1,Dy_accu,21.001
27,135,0.727,4.96,0.147,3.87,38.6,Dy_accu,21.005
28,140,0.895,6.29,0.142,4.92,47.5,Dy_accu,21.006
29,145,1.1,7.99,0.137,6.24,58.3,Dy_accu,21.006
30,150,1.33,10.1,0.132,7.93,70.8,Dy_accu,21.006
31,155,1.62,12.9,0.125,10.1,85.7,Dy_accu,21.002
32,160,1.94,16.3,0.119,12.8,103,Dy_accu,20.997
33,165,2.33,20.7,0.112,16.2,123,Dy_accu,20.993
34,170,2.77,26.3,0.105,20.6,147,Dy_accu,20.99
35,175,3.28,33.4,0.098,26.1,174,Dy_accu,20.992
36,180,3.86,42.5,0.0909,33.2,205,Dy_accu,20.993
37,185,4.53,53.9,0.0839,42.1,240,Dy_accu,20.994
38,190,5.28,68.4,0.0772,53.5,280,Dy_accu,20.996
39,195,6.15,86.9,0.0707,67.9,326,Dy_accu,20.999
40,200,7.12,110,0.0645,86.2,378,Dy_accu,21.001
41,205,8.23,140,0.0587,109,437,Dy_accu,21.003
42,210,9.57,178,0.0538,139,508,Dy_accu,21.006
43,215,11.2,226,0.0495,176,593,Dy_accu,21.008
44,220,13,287,0.0454,224,691,Dy_accu,21.01
45,225,15,364,0.0413,284,797,Dy_accu,21.009
46,230,17.6,462,0.0381,361,935,Dy_accu,21.004
47,235,20.7,586,0.0352,459,1.1,Dy_accu,20.999
48,240,24.1,745,0.0324,582,1.28,Dy_accu,20.997
49,245,28,945,0.0296,739,1.49,Dy_accu,20.993
50,250,32.6,1200,0.0271,938,1.73,Dy_accu,20.995
,,,,,,,,
Interval:,,,2,,,,,
Number of Data Points:,,,10,,,,,
,,,,,,,,
Time Setting:,,,"10 Meas. Pts., Reset Strain",,,,,
,,,Meas. Pt. Duration 1 s,,,,,
Measuring Profile:,,,,,,,,
  Shear Rate,,,"d(gamma)/dt = 1,200 1/s",,,,,
,,,,,,,,
Meas. Pts.,Time,Shear Stress,Shear Rate,Viscosity,Speed,Torque,Status,Temperature
,[s],[Pa],[1/s],[Pa·s],[1/min],[µNm],[],[°C]
1,251,32.5,1200,0.0271,938,1.72,Dy_accu,20.996
2,252,32.4,1200,0.027,938,1.72,Dy_accu,20.996
3,253,32.4,1200,0.027,938,1.72,Dy_accu,20.996
4,254,32.5,1200,0.027,938,1.72,Dy_accu,20.998
5,255,32.5,1200,0.027,938,1.72,Dy_accu,20.998
6,256,32.4,1200,0.027,938,1.72,Dy_accu,20.999
7,257,32.3,1200,0.0269,938,1.71,Dy_accu,21.001
8,258,32.4,1200,0.027,938,1.72,Dy_accu,21
9,259,32.4,1200,0.027,938,1.72,Dy_accu,21.002
10,260,32.4,1200,0.027,938,1.72,Dy_accu,21.002
,,,,,,,,
Interval:,,,3,,,,,
Number of Data Points:,,,50,,,,,
,,,,,,,,
Time Setting:,,,50 Meas. Pts.,,,,,
,,,Meas. Pt. Duration 5 s,,,,,
Measuring Profile:,,,,,,,,
  Shear Rate,,,"d(gamma)/dt = 1,200 ... 0.01 1/s log",,,,,
,,,,,,,,
Meas. Pts.,Time,Shear Stress,Shear Rate,Viscosity,Speed,Torque,Status,Temperature
,[s],[Pa],[1/s],[Pa·s],[1/min],[µNm],[],[°C]
1,265,32.5,1200,0.0271,938,1.72,Dy_accu,21.004
2,270,27.6,945,0.0292,739,1.46,Dy_accu,21.008
3,275,23.8,745,0.032,582,1.26,Dy_accu,21.01
4,280,20.6,586,0.0351,459,1.09,Dy_accu,21.01
5,285,17.7,462,0.0384,361,941,Dy_accu,21.005
6,290,15.3,364,0.042,284,811,Dy_accu,21.001
7,295,13.2,287,0.046,224,700,Dy_accu,20.994
8,300,11.3,226,0.0502,176,601,Dy_accu,20.989
9,305,9.69,178,0.0545,139,515,Dy_accu,20.988
10,310,8.24,140,0.0588,110,437,Dy_accu,20.988
11,315,6.97,110,0.0632,86.2,370,Dy_accu,20.99
12,320,5.88,86.9,0.0677,67.9,312,Dy_accu,20.992
13,325,4.95,68.4,0.0723,53.5,263,Dy_accu,20.994
14,330,4.15,53.9,0.0771,42.1,220,Dy_accu,20.996
15,335,3.48,42.5,0.0819,33.2,185,Dy_accu,20.998
16,340,2.91,33.4,0.0869,26.2,154,Dy_accu,20.999
17,345,2.42,26.3,0.092,20.6,129,Dy_accu,21.002
18,350,2.01,20.8,0.0971,16.2,107,Dy_accu,21.005
19,355,1.67,16.3,0.102,12.8,88.5,Dy_accu,21.006
20,360,1.38,12.9,0.107,10.1,73,Dy_accu,21.008
21,365,1.13,10.1,0.111,7.93,60,Dy_accu,21.009
22,370,0.924,7.99,0.116,6.25,49.1,Dy_accu,21.005
23,375,0.754,6.29,0.12,4.92,40,Dy_accu,21.002
24,380,0.615,4.96,0.124,3.87,32.6,Dy_accu,20.995
25,385,0.496,3.9,0.127,3.05,26.3,Dy_accu,20.993
26,390,0.4,3.07,0.13,2.4,21.3,Dy_accu,20.991
27,395,0.323,2.42,0.134,1.89,17.2,Dy_accu,20.992
28,400,0.261,1.91,0.137,1.49,13.8,Dy_accu,20.994
29,405,0.21,1.5,0.14,1.17,11.2,Dy_accu,20.995
30,410,0.169,1.18,0.143,0.925,8.98,Dy_accu,20.997
31,415,0.136,0.932,0.146,0.729,7.22,Dy_accu,20.999
32,420,0.108,0.734,0.147,0.574,5.74,Dy_accu,21.001
33,425,0.0869,0.578,0.15,0.452,4.61,Dy_accu,21.003
34,430,0.0698,0.456,0.153,0.356,3.7,Dy_accu,21.006
35,435,0.0558,0.359,0.156,0.281,2.96,Dy_accu,21.008
36,440,0.0448,0.283,0.159,0.221,2.38,Dy_accu,21.009
37,445,0.0357,0.223,0.16,0.174,1.89,Dy_accu,21.007
38,450,0.028,0.175,0.159,0.137,1.48,Dy_accu,21.003
39,455,0.0222,0.138,0.161,0.108,1.18,Dy_accu,20.998
40,460,0.0173,0.109,0.159,0.0851,0.918,Dy_accu,20.994
41,465,0.0138,0.0857,0.161,0.067,0.734,Dy_accu,20.994
42,470,0.0106,0.0675,0.158,0.0528,0.565,Dy_accu,20.993
43,475,0.00826,0.0532,0.155,0.0416,0.439,Dy_accu,20.995
44,480,0.00631,0.0419,0.151,0.0327,0.335,Dy_accu,20.997
45,485,0.00479,0.033,0.145,0.0258,0.254,Dy_accu,21
46,490,0.00366,0.026,0.141,0.0203,0.194,Dy_accu,21.001
47,495,0.00276,0.0205,0.135,0.016,0.146,Dy_accu,21.003
48,500,0.00204,0.0161,0.126,0.0126,0.108,Dy_accu,21.006
49,505,0.00146,0.0127,0.115,0.00993,0.0774,Dy_accu,21.008
50,510,0.00103,0.01,0.103,0.00782,0.0546,Dy_accu,21.008
,,,,,,,,
Data Series Information,,,,,,,,
Name:,,,Scatter study - HFC - PAC4 2nd batch - 2,,,,,
Sample:,,,"Dist. H2O + 4 g/L PAC, 2nd batch",,,,,
Operator:,,,Alex,,,,,
Remarks:,,,Bergen,,,,,
Number of Intervals:,,,3,,,,,
Application:,,,RHEOPLUS/32 V3.61 21006089-33024,,,,,
Device:,,,"MCR102 SN81115860; FW3.86; Slot(4,-1); Adj(69,0)d",,,,,
Measuring Date/Time:,,,08/07/2015; 19:11 PM,,,,,
Measuring System:,,,CC27-SN26350; d=0 mm,,,,,
Accessories:,,,TU1=C-PTD200-SN81077144,,,,,
,,,,,,,,
Calculating Constants:,,,,,,,,
- Csr [min/s]:,,,12.789.756,,,,,
- Css [Pa/mNm]:,,,18.841.121,,,,,
- Start Delay Time [s]:,,,7.358,,,,,
- Substance Density [rho]:,,,1,,,,,
- Measurement Type:,,,2,,,,,
- Axial Compliance [m/N]:,,,1.00E-06,,,,,
- Position [m]:,,,1.00E-06,,,,,
,,,,,,,,
Interval:,,,1,,,,,
Number of Data Points:,,,50,,,,,
,,,,,,,,
Time Setting:,,,50 Meas. Pts.,,,,,
,,,Meas. Pt. Duration 5 s,,,,,
Measuring Profile:,,,,,,,,
  Shear Rate,,,"d(gamma)/dt = 0.01 ... 1,200 1/s log",,,,,
,,,,,,,,
Meas. Pts.,Time,Shear Stress,Shear Rate,Viscosity,Speed,Torque,Status,Temperature
,[s],[Pa],[1/s],[Pa·s],[1/min],[µNm],[],[°C]
1,5,0.00285,0.01,0.285,0.00782,0.151,Dy_accu,20.978
2,10,0.00336,0.0127,0.264,0.00993,0.178,Dy_accu,20.977
3,15,0.00397,0.0161,0.246,0.0126,0.211,Dy_accu,20.975
4,20,0.00483,0.0205,0.236,0.016,0.256,Dy_accu,20.972
5,25,0.00588,0.026,0.226,0.0203,0.312,Dy_accu,20.97
6,30,0.00716,0.033,0.217,0.0258,0.38,Dy_accu,20.97
7,35,0.0088,0.0419,0.21,0.0327,0.467,Dy_accu,20.973
8,40,0.0109,0.0532,0.205,0.0416,0.577,Dy_accu,20.976
9,45,0.0135,0.0675,0.2,0.0528,0.716,Dy_accu,20.98
10,50,0.0167,0.0857,0.195,0.067,0.888,Dy_accu,20.986
11,55,0.0211,0.109,0.194,0.085,1.12,Dy_accu,20.991
12,60,0.0266,0.138,0.192,0.108,1.41,Dy_accu,20.994
13,65,0.0331,0.175,0.189,0.137,1.76,Dy_accu,20.996
14,70,0.0413,0.223,0.185,0.174,2.19,Dy_accu,20.995
15,75,0.0513,0.283,0.182,0.221,2.72,Dy_accu,20.992
16,80,0.0634,0.359,0.177,0.281,3.37,Dy_accu,20.988
17,85,0.0793,0.456,0.174,0.356,4.21,Dy_accu,20.984
18,90,0.1,0.578,0.173,0.452,5.32,Dy_accu,20.983
19,95,0.126,0.734,0.171,0.574,6.68,Dy_accu,20.984
20,100,0.158,0.932,0.169,0.729,8.38,Dy_accu,20.986
21,105,0.199,1.18,0.169,0.925,10.6,Dy_accu,20.989
22,110,0.251,1.5,0.167,1.17,13.3,Dy_accu,20.994
23,115,0.317,1.91,0.166,1.49,16.8,Dy_accu,20.997
24,120,0.398,2.42,0.164,1.89,21.1,Dy_accu,21.001
25,125,0.498,3.07,0.162,2.4,26.4,Dy_accu,21.003
26,130,0.617,3.9,0.158,3.05,32.7,Dy_accu,21.004
27,135,0.763,4.96,0.154,3.87,40.5,Dy_accu,21
28,140,0.941,6.29,0.15,4.92,50,Dy_accu,20.997
29,145,1.15,7.99,0.144,6.24,61,Dy_accu,20.992
30,150,1.4,10.1,0.138,7.93,74.2,Dy_accu,20.988
31,155,1.69,12.9,0.131,10.1,89.8,Dy_accu,20.988
32,160,2.03,16.3,0.124,12.8,108,Dy_accu,20.989
33,165,2.43,20.7,0.117,16.2,129,Dy_accu,20.991
34,170,2.89,26.3,0.11,20.6,153,Dy_accu,20.994
35,175,3.41,33.4,0.102,26.1,181,Dy_accu,20.998
36,180,4.01,42.5,0.0944,33.2,213,Dy_accu,21.001
37,185,4.69,53.9,0.087,42.1,249,Dy_accu,21.005
38,190,5.46,68.4,0.0798,53.5,290,Dy_accu,21.005
39,195,6.34,86.9,0.0729,67.9,336,Dy_accu,21.003
40,200,7.33,110,0.0665,86.2,389,Dy_accu,21
41,205,8.47,140,0.0605,109,449,Dy_accu,20.995
42,210,9.83,178,0.0553,139,522,Dy_accu,20.992
43,215,11.5,226,0.0509,176,610,Dy_accu,20.991
44,220,13.4,287,0.0467,224,711,Dy_accu,20.992
45,225,15.4,364,0.0423,284,816,Dy_accu,20.995
46,230,18.1,462,0.0391,361,959,Dy_accu,20.999
47,235,21.2,586,0.0362,459,1.13,Dy_accu,21.003
48,240,24.7,744,0.0332,582,1.31,Dy_accu,21.007
49,245,28.6,945,0.0303,739,1.52,Dy_accu,21.01
50,250,33.2,1200,0.0276,938,1.76,Dy_accu,21.01
,,,,,,,,
Interval:,,,2,,,,,
Number of Data Points:,,,10,,,,,
,,,,,,,,
Time Setting:,,,"10 Meas. Pts., Reset Strain",,,,,
,,,Meas. Pt. Duration 1 s,,,,,
Measuring Profile:,,,,,,,,
  Shear Rate,,,"d(gamma)/dt = 1,200 1/s",,,,,
,,,,,,,,
Meas. Pts.,Time,Shear Stress,Shear Rate,Viscosity,Speed,Torque,Status,Temperature
,[s],[Pa],[1/s],[Pa·s],[1/min],[µNm],[],[°C]
1,251,33.2,1200,0.0277,938,1.76,Dy_accu,21.01
2,252,33.2,1200,0.0277,938,1.76,Dy_accu,21.009
3,253,33.2,1200,0.0277,938,1.76,Dy_accu,21.008
4,254,33.2,1200,0.0277,938,1.76,Dy_accu,21.008
5,255,33,1200,0.0275,938,1.75,Dy_accu,21.008
6,256,33.1,1200,0.0276,938,1.76,Dy_accu,21.007
7,257,33.1,1200,0.0275,938,1.75,Dy_accu,21.008
8,258,33.1,1200,0.0276,938,1.76,Dy_accu,21.007
9,259,33.1,1200,0.0276,938,1.76,Dy_accu,21.006
10,260,33,1200,0.0275,938,1.75,Dy_accu,21.005
,,,,,,,,
Interval:,,,3,,,,,
Number of Data Points:,,,50,,,,,
,,,,,,,,
Time Setting:,,,50 Meas. Pts.,,,,,
,,,Meas. Pt. Duration 5 s,,,,,
Measuring Profile:,,,,,,,,
  Shear Rate,,,"d(gamma)/dt = 1,200 ... 0.01 1/s log",,,,,
,,,,,,,,
Meas. Pts.,Time,Shear Stress,Shear Rate,Viscosity,Speed,Torque,Status,Temperature
,[s],[Pa],[1/s],[Pa·s],[1/min],[µNm],[],[°C]
1,265,33,1200,0.0275,938,1.75,Dy_accu,21.002
2,270,28.3,945,0.0299,739,1.5,Dy_accu,20.999
3,275,24.3,745,0.0327,582,1.29,Dy_accu,20.995
4,280,21,586,0.0357,459,1.11,Dy_accu,20.991
5,285,18.1,462,0.0391,361,958,Dy_accu,20.99
6,290,15.6,364,0.0428,284,827,Dy_accu,20.992
7,295,13.5,287,0.0469,224,714,Dy_accu,20.994
8,300,11.6,226,0.0513,176,615,Dy_accu,20.997
9,305,9.94,178,0.0559,139,528,Dy_accu,20.999
10,310,8.47,140,0.0604,110,449,Dy_accu,21.003
11,315,7.17,110,0.065,86.2,381,Dy_accu,21.006
12,320,6.06,86.9,0.0698,67.9,322,Dy_accu,21.007
13,325,5.11,68.4,0.0747,53.5,271,Dy_accu,21.005
14,330,4.3,53.9,0.0798,42.1,228,Dy_accu,21.001
15,335,3.61,42.5,0.0851,33.2,192,Dy_accu,20.995
16,340,3.02,33.4,0.0904,26.2,161,Dy_accu,20.991
17,345,2.52,26.3,0.0958,20.6,134,Dy_accu,20.99
18,350,2.1,20.8,0.101,16.2,111,Dy_accu,20.99
19,355,1.74,16.3,0.107,12.8,92.5,Dy_accu,20.993
20,360,1.44,12.9,0.112,10.1,76.3,Dy_accu,20.994
21,365,1.18,10.1,0.117,7.93,62.7,Dy_accu,20.997
22,370,0.97,7.99,0.121,6.24,51.5,Dy_accu,21
23,375,0.79,6.29,0.126,4.92,41.9,Dy_accu,21.003
24,380,0.643,4.96,0.13,3.87,34.1,Dy_accu,21.007
25,385,0.523,3.9,0.134,3.05,27.8,Dy_accu,21.008
26,390,0.422,3.07,0.137,2.4,22.4,Dy_accu,21.009
27,395,0.34,2.42,0.14,1.89,18,Dy_accu,21.006
28,400,0.273,1.91,0.143,1.49,14.5,Dy_accu,21
29,405,0.219,1.5,0.146,1.17,11.6,Dy_accu,20.996
30,410,0.176,1.18,0.149,0.925,9.35,Dy_accu,20.993
31,415,0.142,0.932,0.152,0.729,7.53,Dy_accu,20.993
32,420,0.113,0.734,0.155,0.574,6.02,Dy_accu,20.995
33,425,0.0918,0.578,0.159,0.452,4.87,Dy_accu,20.997
34,430,0.0738,0.456,0.162,0.356,3.92,Dy_accu,21
35,435,0.0597,0.359,0.166,0.281,3.17,Dy_accu,21.002
36,440,0.0479,0.283,0.169,0.221,2.54,Dy_accu,21.006
37,445,0.0382,0.223,0.172,0.174,2.03,Dy_accu,21.009
38,450,0.0308,0.175,0.176,0.137,1.63,Dy_accu,21.01
39,455,0.0245,0.138,0.177,0.108,1.3,Dy_accu,21.006
40,460,0.0198,0.109,0.182,0.0851,1.05,Dy_accu,21.002
41,465,0.0163,0.0857,0.19,0.067,0.864,Dy_accu,20.998
42,470,0.0131,0.0675,0.195,0.0528,0.697,Dy_accu,20.994
43,475,0.0108,0.0532,0.204,0.0416,0.575,Dy_accu,20.993
44,480,0.00871,0.0419,0.208,0.0327,0.463,Dy_accu,20.993
45,485,0.00723,0.033,0.219,0.0258,0.384,Dy_accu,20.995
46,490,0.00594,0.026,0.229,0.0203,0.315,Dy_accu,20.998
47,495,0.00496,0.0205,0.243,0.016,0.263,Dy_accu,21
48,500,0.0042,0.0161,0.261,0.0126,0.223,Dy_accu,21.002
49,505,0.00364,0.0127,0.287,0.00993,0.193,Dy_accu,21.007
50,510,0.00319,0.01,0.319,0.00782,0.169,Dy_accu,21.01
,,,,,,,,
Data Series Information,,,,,,,,
Name:,,,Scatter study - HFC - PAC4 2nd batch - 3,,,,,
Sample:,,,"Dist. H2O + 4 g/L PAC, 2nd batch",,,,,
Operator:,,,Alex,,,,,
Remarks:,,,Bergen,,,,,
Number of Intervals:,,,3,,,,,
Application:,,,RHEOPLUS/32 V3.61 21006089-33024,,,,,
Device:,,,"MCR102 SN81115860; FW3.86; Slot(4,-1); Adj(69,0)d",,,,,
Measuring Date/Time:,,,08/07/2015; 19:35 PM,,,,,
Measuring System:,,,CC27-SN26350; d=0 mm,,,,,
Accessories:,,,TU1=C-PTD200-SN81077144,,,,,
,,,,,,,,
Calculating Constants:,,,,,,,,
- Csr [min/s]:,,,12.789.756,,,,,
- Css [Pa/mNm]:,,,18.841.121,,,,,
- Start Delay Time [s]:,,,7.366,,,,,
- Substance Density [rho]:,,,1,,,,,
- Measurement Type:,,,2,,,,,
- Axial Compliance [m/N]:,,,1.00E-06,,,,,
- Position [m]:,,,1.00E-06,,,,,
,,,,,,,,
Interval:,,,1,,,,,
Number of Data Points:,,,50,,,,,
,,,,,,,,
Time Setting:,,,50 Meas. Pts.,,,,,
,,,Meas. Pt. Duration 5 s,,,,,
Measuring Profile:,,,,,,,,
  Shear Rate,,,"d(gamma)/dt = 0.01 ... 1,200 1/s log",,,,,
,,,,,,,,
Meas. Pts.,Time,Shear Stress,Shear Rate,Viscosity,Speed,Torque,Status,Temperature
,[s],[Pa],[1/s],[Pa·s],[1/min],[µNm],[],[°C]
1,5,0.00215,0.01,0.215,0.00782,0.114,Dy_accu,20.991
2,10,0.00277,0.0127,0.218,0.00993,0.147,Dy_accu,20.995
3,15,0.00349,0.0161,0.217,0.0126,0.185,Dy_accu,20.996
4,20,0.00419,0.0205,0.205,0.016,0.222,Dy_accu,21
5,25,0.00526,0.026,0.203,0.0203,0.279,Dy_accu,21.003
6,30,0.00656,0.033,0.199,0.0258,0.348,Dy_accu,21.007
7,35,0.00837,0.0419,0.2,0.0327,0.444,Dy_accu,21.008
8,40,0.0103,0.0532,0.193,0.0416,0.546,Dy_accu,21.006
9,45,0.0131,0.0675,0.194,0.0528,0.696,Dy_accu,21.002
10,50,0.0167,0.0857,0.195,0.067,0.888,Dy_accu,20.998
11,55,0.0213,0.109,0.196,0.0851,1.13,Dy_accu,20.994
12,60,0.0267,0.138,0.193,0.108,1.42,Dy_accu,20.992
13,65,0.0337,0.175,0.192,0.137,1.79,Dy_accu,20.991
14,70,0.0421,0.223,0.189,0.174,2.23,Dy_accu,20.992
15,75,0.0527,0.283,0.186,0.221,2.8,Dy_accu,20.997
16,80,0.0662,0.359,0.185,0.281,3.52,Dy_accu,20.998
17,85,0.0832,0.456,0.183,0.356,4.41,Dy_accu,21.003
18,90,0.104,0.578,0.181,0.452,5.55,Dy_accu,21.006
19,95,0.131,0.734,0.179,0.574,6.96,Dy_accu,21.008
20,100,0.165,0.932,0.177,0.729,8.77,Dy_accu,21.007
21,105,0.207,1.18,0.175,0.925,11,Dy_accu,21.004
22,110,0.26,1.5,0.173,1.17,13.8,Dy_accu,21.001
23,115,0.326,1.91,0.171,1.49,17.3,Dy_accu,20.996
24,120,0.408,2.42,0.168,1.89,21.6,Dy_accu,20.992
25,125,0.51,3.07,0.166,2.4,27.1,Dy_accu,20.99
26,130,0.635,3.9,0.163,3.05,33.7,Dy_accu,20.99
27,135,0.785,4.96,0.158,3.87,41.7,Dy_accu,20.994
28,140,0.964,6.29,0.153,4.92,51.2,Dy_accu,20.997
29,145,1.18,7.99,0.148,6.24,62.6,Dy_accu,21.001
30,150,1.43,10.1,0.141,7.93,76.1,Dy_accu,21.004
31,155,1.73,12.9,0.134,10.1,91.8,Dy_accu,21.007
32,160,2.08,16.3,0.127,12.8,110,Dy_accu,21.009
33,165,2.49,20.7,0.12,16.2,132,Dy_accu,21.008
34,170,2.95,26.3,0.112,20.6,157,Dy_accu,21.005
35,175,3.49,33.4,0.104,26.1,185,Dy_accu,21.001
36,180,4.09,42.5,0.0964,33.2,217,Dy_accu,20.996
37,185,4.78,53.9,0.0887,42.1,254,Dy_accu,20.992
38,190,5.56,68.4,0.0812,53.5,295,Dy_accu,20.993
39,195,6.44,86.9,0.0741,67.9,342,Dy_accu,20.993
40,200,7.42,110,0.0673,86.2,394,Dy_accu,20.997
41,205,8.56,140,0.0611,109,454,Dy_accu,21
42,210,9.94,178,0.0559,139,528,Dy_accu,21.003
43,215,11.6,226,0.0514,176,616,Dy_accu,21.007
44,220,13.5,287,0.0472,224,718,Dy_accu,21.01
45,225,15.5,364,0.0426,284,823,Dy_accu,21.009
46,230,18,462,0.039,361,955,Dy_accu,21.007
47,235,21.2,586,0.0362,459,1.13,Dy_accu,21.003
48,240,25,744,0.0336,582,1.33,Dy_accu,20.999
49,245,28.9,945,0.0306,739,1.53,Dy_accu,20.996
50,250,33.6,1200,0.028,938,1.78,Dy_accu,20.993
,,,,,,,,
Interval:,,,2,,,,,
Number of Data Points:,,,10,,,,,
,,,,,,,,
Time Setting:,,,"10 Meas. Pts., Reset Strain",,,,,
,,,Meas. Pt. Duration 1 s,,,,,
Measuring Profile:,,,,,,,,
  Shear Rate,,,"d(gamma)/dt = 1,200 1/s",,,,,
,,,,,,,,
Meas. Pts.,Time,Shear Stress,Shear Rate,Viscosity,Speed,Torque,Status,Temperature
,[s],[Pa],[1/s],[Pa·s],[1/min],[µNm],[],[°C]
1,251,33.5,1200,0.0279,938,1.78,Dy_accu,20.991
2,252,33.5,1200,0.0279,938,1.78,Dy_accu,20.993
3,253,33.5,1200,0.0279,938,1.78,Dy_accu,20.993
4,254,33.3,1200,0.0277,938,1.77,Dy_accu,20.993
5,255,33.4,1200,0.0278,938,1.77,Dy_accu,20.995
6,256,33.5,1200,0.0279,938,1.78,Dy_accu,20.995
7,257,33.5,1200,0.0279,938,1.78,Dy_accu,20.994
8,258,33.6,1200,0.028,938,1.78,Dy_accu,20.995
9,259,33.5,1200,0.0279,938,1.78,Dy_accu,20.997
10,260,33.4,1200,0.0278,938,1.77,Dy_accu,20.998
,,,,,,,,
Interval:,,,3,,,,,
Number of Data Points:,,,50,,,,,
,,,,,,,,
Time Setting:,,,50 Meas. Pts.,,,,,
,,,Meas. Pt. Duration 5 s,,,,,
Measuring Profile:,,,,,,,,
  Shear Rate,,,"d(gamma)/dt = 1,200 ... 0.01 1/s log",,,,,
,,,,,,,,
Meas. Pts.,Time,Shear Stress,Shear Rate,Viscosity,Speed,Torque,Status,Temperature
,[s],[Pa],[1/s],[Pa·s],[1/min],[µNm],[],[°C]
1,265,33.4,1200,0.0278,938,1.77,Dy_accu,21.001
2,270,28.6,945,0.0303,739,1.52,Dy_accu,21.005
3,275,24.7,745,0.0332,582,1.31,Dy_accu,21.01
4,280,21.3,586,0.0363,459,1.13,Dy_accu,21.011
5,285,18.4,462,0.0398,361,976,Dy_accu,21.01
6,290,15.9,364,0.0437,284,844,Dy_accu,21.007
7,295,13.8,287,0.048,224,730,Dy_accu,21.003
8,300,11.8,226,0.0524,176,628,Dy_accu,21
9,305,10.1,178,0.057,139,538,Dy_accu,20.996
10,310,8.62,140,0.0616,110,458,Dy_accu,20.992
11,315,7.3,110,0.0662,86.2,387,Dy_accu,20.99
12,320,6.16,86.9,0.0709,67.9,327,Dy_accu,20.992
13,325,5.19,68.4,0.0758,53.5,275,Dy_accu,20.994
14,330,4.36,53.9,0.0809,42.1,231,Dy_accu,20.998
15,335,3.66,42.5,0.0861,33.2,194,Dy_accu,21.003
16,340,3.06,33.4,0.0915,26.2,162,Dy_accu,21.006
17,345,2.55,26.3,0.0969,20.6,135,Dy_accu,21.009
18,350,2.12,20.8,0.102,16.2,113,Dy_accu,21.008
19,355,1.76,16.3,0.108,12.8,93.4,Dy_accu,21.006
20,360,1.45,12.9,0.113,10.1,77.2,Dy_accu,21.001
21,365,1.2,10.1,0.118,7.93,63.5,Dy_accu,20.997
22,370,0.979,7.99,0.123,6.24,52,Dy_accu,20.994
23,375,0.801,6.29,0.127,4.92,42.5,Dy_accu,20.991
24,380,0.651,4.96,0.131,3.87,34.6,Dy_accu,20.992
25,385,0.527,3.9,0.135,3.05,28,Dy_accu,20.995
26,390,0.427,3.07,0.139,2.4,22.7,Dy_accu,20.998
27,395,0.346,2.42,0.143,1.89,18.3,Dy_accu,21.002
28,400,0.278,1.91,0.146,1.49,14.8,Dy_accu,21.005
29,405,0.224,1.5,0.149,1.17,11.9,Dy_accu,21.008
30,410,0.179,1.18,0.151,0.925,9.51,Dy_accu,21.008
31,415,0.143,0.932,0.153,0.729,7.58,Dy_accu,21.007
32,420,0.114,0.734,0.155,0.574,6.05,Dy_accu,21.004
33,425,0.0911,0.578,0.158,0.452,4.84,Dy_accu,21
34,430,0.0729,0.456,0.16,0.356,3.87,Dy_accu,20.996
35,435,0.0579,0.359,0.161,0.281,3.07,Dy_accu,20.993
36,440,0.0464,0.283,0.164,0.221,2.46,Dy_accu,20.991
37,445,0.0371,0.223,0.167,0.174,1.97,Dy_accu,20.993
38,450,0.0294,0.175,0.168,0.137,1.56,Dy_accu,20.996
39,455,0.0233,0.138,0.169,0.108,1.24,Dy_accu,21
40,460,0.0183,0.109,0.168,0.0851,0.971,Dy_accu,21.005
41,465,0.0143,0.0857,0.167,0.067,0.761,Dy_accu,21.008
42,470,0.0115,0.0675,0.17,0.0528,0.609,Dy_accu,21.008
43,475,0.00887,0.0532,0.167,0.0416,0.471,Dy_accu,21.007
44,480,0.00691,0.0419,0.165,0.0327,0.367,Dy_accu,21.004
45,485,0.0052,0.033,0.158,0.0258,0.276,Dy_accu,21
46,490,0.00375,0.026,0.144,0.0203,0.199,Dy_accu,20.996
47,495,0.00268,0.0205,0.131,0.016,0.142,Dy_accu,20.993
48,500,0.00187,0.0161,0.116,0.0126,0.0994,Dy_accu,20.991
49,505,0.00125,0.0127,0.0984,0.00993,0.0663,Dy_accu,20.991
50,510,0.000835,0.01,0.0836,0.00782,0.0443,"M- ,Dy_",20.995
,,,,,,,,
Data Series Information,,,,,,,,
Name:,,,Scatter study - HFC - PAC4 2nd batch - 4,,,,,
Sample:,,,"Dist. H2O + 4 g/L PAC, 2nd batch",,,,,
Operator:,,,Alex,,,,,
Remarks:,,,Bergen,,,,,
Number of Intervals:,,,3,,,,,
Application:,,,RHEOPLUS/32 V3.61 21006089-33024,,,,,
Device:,,,"MCR102 SN81115860; FW3.86; Slot(4,-1); Adj(69,0)d",,,,,
Measuring Date/Time:,,,08/07/2015; 19:53 PM,,,,,
Measuring System:,,,CC27-SN26350; d=0 mm,,,,,
Accessories:,,,TU1=C-PTD200-SN81077144,,,,,
,,,,,,,,
Calculating Constants:,,,,,,,,
- Csr [min/s]:,,,12.789.756,,,,,
- Css [Pa/mNm]:,,,18.841.121,,,,,
- Start Delay Time [s]:,,,7.302,,,,,
- Substance Density [rho]:,,,1,,,,,
- Measurement Type:,,,2,,,,,
- Axial Compliance [m/N]:,,,1.00E-06,,,,,
- Position [m]:,,,1.00E-06,,,,,
,,,,,,,,
Interval:,,,1,,,,,
Number of Data Points:,,,50,,,,,
,,,,,,,,
Time Setting:,,,50 Meas. Pts.,,,,,
,,,Meas. Pt. Duration 5 s,,,,,
Measuring Profile:,,,,,,,,
  Shear Rate,,,"d(gamma)/dt = 0.01 ... 1,200 1/s log",,,,,
,,,,,,,,
Meas. Pts.,Time,Shear Stress,Shear Rate,Viscosity,Speed,Torque,Status,Temperature
,[s],[Pa],[1/s],[Pa·s],[1/min],[µNm],[],[°C]
1,5,0.00219,0.01,0.219,0.00782,0.116,Dy_accu,20.98
2,10,0.0027,0.0127,0.213,0.00993,0.143,Dy_accu,20.978
3,15,0.00336,0.0161,0.208,0.0126,0.178,Dy_accu,20.981
4,20,0.00411,0.0205,0.201,0.016,0.218,Dy_accu,20.985
5,25,0.0053,0.026,0.204,0.0203,0.281,Dy_accu,20.991
6,30,0.00664,0.033,0.201,0.0258,0.352,Dy_accu,20.997
7,35,0.00813,0.0419,0.194,0.0327,0.432,Dy_accu,21
8,40,0.0102,0.0532,0.193,0.0416,0.544,Dy_accu,21.001
9,45,0.0132,0.0675,0.195,0.0528,0.699,Dy_accu,21.001
10,50,0.0166,0.0857,0.194,0.067,0.88,Dy_accu,21
11,55,0.0209,0.109,0.192,0.085,1.11,Dy_accu,20.998
12,60,0.0264,0.138,0.191,0.108,1.4,Dy_accu,20.995
13,65,0.0334,0.175,0.19,0.137,1.77,Dy_accu,20.992
14,70,0.0418,0.223,0.188,0.174,2.22,Dy_accu,20.99
15,75,0.0519,0.283,0.184,0.221,2.75,Dy_accu,20.988
16,80,0.0647,0.359,0.18,0.281,3.44,Dy_accu,20.987
17,85,0.0818,0.456,0.179,0.356,4.34,Dy_accu,20.989
18,90,0.103,0.578,0.178,0.452,5.47,Dy_accu,20.992
19,95,0.13,0.734,0.177,0.574,6.89,Dy_accu,20.996
20,100,0.163,0.932,0.175,0.729,8.67,Dy_accu,21.002
21,105,0.207,1.18,0.175,0.925,11,Dy_accu,21.004
22,110,0.26,1.5,0.173,1.17,13.8,Dy_accu,21.005
23,115,0.328,1.91,0.172,1.49,17.4,Dy_accu,21.004
24,120,0.412,2.42,0.17,1.89,21.9,Dy_accu,21.002
25,125,0.514,3.07,0.167,2.4,27.3,Dy_accu,21
26,130,0.637,3.9,0.163,3.05,33.8,Dy_accu,20.996
27,135,0.79,4.96,0.159,3.87,41.9,Dy_accu,20.993
28,140,0.972,6.29,0.154,4.92,51.6,Dy_accu,20.99
29,145,1.19,7.99,0.148,6.24,62.9,Dy_accu,20.988
30,150,1.44,10.1,0.142,7.93,76.6,Dy_accu,20.988
31,155,1.74,12.9,0.135,10.1,92.5,Dy_accu,20.992
32,160,2.09,16.3,0.128,12.8,111,Dy_accu,20.997
33,165,2.5,20.7,0.12,16.2,133,Dy_accu,21.001
34,170,2.97,26.3,0.113,20.6,157,Dy_accu,21.005
35,175,3.5,33.4,0.105,26.1,186,Dy_accu,21.006
36,180,4.1,42.5,0.0966,33.2,218,Dy_accu,21.005
37,185,4.79,53.9,0.0889,42.1,254,Dy_accu,21.002
38,190,5.57,68.4,0.0813,53.5,295,Dy_accu,21
39,195,6.44,86.9,0.0742,67.9,342,Dy_accu,20.997
40,200,7.43,110,0.0674,86.2,394,Dy_accu,20.994
41,205,8.56,140,0.0612,109,455,Dy_accu,20.991
42,210,9.94,178,0.0559,139,528,Dy_accu,20.99
43,215,11.6,226,0.0515,176,617,Dy_accu,20.993
44,220,13.6,287,0.0474,224,720,Dy_accu,20.996
45,225,15.6,364,0.043,284,830,Dy_accu,21.002
46,230,18.3,462,0.0396,361,970,Dy_accu,21.007
47,235,21.5,586,0.0367,459,1.14,Dy_accu,21.011
48,240,25.1,744,0.0337,582,1.33,Dy_accu,21.012
49,245,29.1,945,0.0308,739,1.54,Dy_accu,21.012
50,250,33.8,1200,0.0282,938,1.79,Dy_accu,21.011
,,,,,,,,
Interval:,,,2,,,,,
Number of Data Points:,,,10,,,,,
,,,,,,,,
Time Setting:,,,"10 Meas. Pts., Reset Strain",,,,,
,,,Meas. Pt. Duration 1 s,,,,,
Measuring Profile:,,,,,,,,
  Shear Rate,,,"d(gamma)/dt = 1,200 1/s",,,,,
,,,,,,,,
Meas. Pts.,Time,Shear Stress,Shear Rate,Viscosity,Speed,Torque,Status,Temperature
,[s],[Pa],[1/s],[Pa·s],[1/min],[µNm],[],[°C]
1,251,33.9,1200,0.0283,938,1.8,Dy_accu,21.01
2,252,33.7,1200,0.0281,938,1.79,Dy_accu,21.011
3,253,33.6,1200,0.028,938,1.78,Dy_accu,21.01
4,254,33.7,1200,0.0281,938,1.79,Dy_accu,21.012
5,255,33.5,1200,0.0279,938,1.78,Dy_accu,21.009
6,256,33.5,1200,0.028,938,1.78,Dy_accu,21.01
7,257,33.5,1200,0.0279,938,1.78,Dy_accu,21.009
8,258,33.6,1200,0.028,938,1.78,Dy_accu,21.009
9,259,33.6,1200,0.028,938,1.78,Dy_accu,21.01
10,260,33.6,1200,0.028,938,1.78,Dy_accu,21.008
,,,,,,,,
Interval:,,,3,,,,,
Number of Data Points:,,,50,,,,,
,,,,,,,,
Time Setting:,,,50 Meas. Pts.,,,,,
,,,Meas. Pt. Duration 5 s,,,,,
Measuring Profile:,,,,,,,,
  Shear Rate,,,"d(gamma)/dt = 1,200 ... 0.01 1/s log",,,,,
,,,,,,,,
Meas. Pts.,Time,Shear Stress,Shear Rate,Viscosity,Speed,Torque,Status,Temperature
,[s],[Pa],[1/s],[Pa·s],[1/min],[µNm],[],[°C]
1,265,33.5,1200,0.0279,938,1.78,Dy_accu,21.007
2,270,28.7,945,0.0303,739,1.52,Dy_accu,21.005
3,275,24.7,745,0.0332,582,1.31,Dy_accu,21.002
4,280,21.3,586,0.0364,459,1.13,Dy_accu,21.001
5,285,18.5,462,0.04,361,979,Dy_accu,20.998
6,290,15.9,364,0.0438,284,846,Dy_accu,20.995
7,295,13.7,287,0.0479,224,729,Dy_accu,20.992
8,300,11.8,226,0.0523,176,627,Dy_accu,20.99
9,305,10.1,178,0.0569,139,537,Dy_accu,20.987
10,310,8.62,140,0.0615,110,457,Dy_accu,20.989
11,315,7.3,110,0.0662,86.2,387,Dy_accu,20.992
12,320,6.17,86.9,0.071,67.9,328,Dy_accu,20.996
13,325,5.21,68.4,0.0761,53.5,276,Dy_accu,21
14,330,4.39,53.9,0.0814,42.1,233,Dy_accu,21.003
15,335,3.69,42.5,0.0869,33.2,196,Dy_accu,21.005
16,340,3.09,33.4,0.0924,26.2,164,Dy_accu,21.003
17,345,2.58,26.3,0.0981,20.6,137,Dy_accu,21.001
18,350,2.15,20.8,0.104,16.2,114,Dy_accu,20.998
19,355,1.79,16.3,0.109,12.8,94.8,Dy_accu,20.996
20,360,1.48,12.9,0.115,10.1,78.4,Dy_accu,20.992
21,365,1.21,10.1,0.12,7.93,64.4,Dy_accu,20.989
22,370,0.997,7.99,0.125,6.25,52.9,Dy_accu,20.989
23,375,0.813,6.29,0.129,4.92,43.1,Dy_accu,20.993
24,380,0.663,4.96,0.134,3.87,35.2,Dy_accu,20.998
25,385,0.539,3.9,0.138,3.05,28.6,Dy_accu,21.002
26,390,0.434,3.07,0.141,2.4,23.1,Dy_accu,21.006
27,395,0.349,2.42,0.144,1.89,18.5,Dy_accu,21.008
28,400,0.282,1.91,0.148,1.49,14.9,Dy_accu,21.006
29,405,0.226,1.5,0.151,1.17,12,Dy_accu,21.004
30,410,0.182,1.18,0.154,0.925,9.67,Dy_accu,21.001
31,415,0.147,0.932,0.157,0.729,7.79,Dy_accu,20.998
32,420,0.118,0.734,0.161,0.574,6.27,Dy_accu,20.994
33,425,0.095,0.578,0.164,0.452,5.04,Dy_accu,20.991
34,430,0.0765,0.456,0.168,0.356,4.06,Dy_accu,20.991
35,435,0.0616,0.359,0.172,0.281,3.27,Dy_accu,20.994
36,440,0.0494,0.283,0.175,0.221,2.62,Dy_accu,20.997
37,445,0.0398,0.223,0.179,0.174,2.11,Dy_accu,21.001
38,450,0.0323,0.175,0.184,0.137,1.72,Dy_accu,21.007
39,455,0.026,0.138,0.188,0.108,1.38,Dy_accu,21.008
40,460,0.0209,0.109,0.192,0.0851,1.11,Dy_accu,21.008
41,465,0.0169,0.0857,0.197,0.067,0.895,Dy_accu,21.006
42,470,0.0139,0.0675,0.206,0.0528,0.739,Dy_accu,21.003
43,475,0.0113,0.0532,0.212,0.0416,0.599,Dy_accu,21.001
44,480,0.00934,0.0419,0.223,0.0327,0.496,Dy_accu,20.996
45,485,0.00761,0.033,0.231,0.0258,0.404,Dy_accu,20.994
46,490,0.00618,0.026,0.238,0.0203,0.328,Dy_accu,20.991
47,495,0.00517,0.0205,0.253,0.016,0.274,Dy_accu,20.993
48,500,0.0043,0.0161,0.267,0.0126,0.228,Dy_accu,20.996
49,505,0.00366,0.0127,0.289,0.00993,0.194,Dy_accu,21
50,510,0.00313,0.01,0.313,0.00782,0.166,Dy_accu,21.004
,,,,,,,,
Data Series Information,,,,,,,,
Name:,,,Scatter study - HFC - PAC4 2nd batch - 5,,,,,
Sample:,,,"Dist. H2O + 4 g/L PAC, 2nd batch",,,,,
Operator:,,,Alex,,,,,
Remarks:,,,Bergen,,,,,
Number of Intervals:,,,3,,,,,
Application:,,,RHEOPLUS/32 V3.61 21006089-33024,,,,,
Device:,,,"MCR102 SN81115860; FW3.86; Slot(4,-1); Adj(69,0)d",,,,,
Measuring Date/Time:,,,08/07/2015; 20:12 PM,,,,,
Measuring System:,,,CC27-SN26350; d=0 mm,,,,,
Accessories:,,,TU1=C-PTD200-SN81077144,,,,,
,,,,,,,,
Calculating Constants:,,,,,,,,
- Csr [min/s]:,,,12.789.756,,,,,
- Css [Pa/mNm]:,,,18.841.121,,,,,
- Start Delay Time [s]:,,,7.279,,,,,
- Substance Density [rho]:,,,1,,,,,
- Measurement Type:,,,2,,,,,
- Axial Compliance [m/N]:,,,1.00E-06,,,,,
- Position [m]:,,,1.00E-06,,,,,
,,,,,,,,
Interval:,,,1,,,,,
Number of Data Points:,,,50,,,,,
,,,,,,,,
Time Setting:,,,50 Meas. Pts.,,,,,
,,,Meas. Pt. Duration 5 s,,,,,
Measuring Profile:,,,,,,,,
  Shear Rate,,,"d(gamma)/dt = 0.01 ... 1,200 1/s log",,,,,
,,,,,,,,
Meas. Pts.,Time,Shear Stress,Shear Rate,Viscosity,Speed,Torque,Status,Temperature
,[s],[Pa],[1/s],[Pa·s],[1/min],[µNm],[],[°C]
1,5,0.000401,0.01,0.04,0.00783,0.0213,"M- ,Dy_",20.974
2,10,0.00111,0.0127,0.0875,0.00992,0.0589,Dy_accu,20.973
3,15,0.00173,0.0161,0.108,0.0126,0.0921,Dy_accu,20.973
4,20,0.00257,0.0205,0.126,0.016,0.137,Dy_accu,20.972
5,25,0.00359,0.026,0.138,0.0203,0.191,Dy_accu,20.974
6,30,0.00504,0.033,0.153,0.0258,0.267,Dy_accu,20.979
7,35,0.00677,0.0419,0.162,0.0327,0.359,Dy_accu,20.986
8,40,0.00904,0.0532,0.17,0.0416,0.48,Dy_accu,20.992
9,45,0.012,0.0675,0.178,0.0528,0.639,Dy_accu,20.995
10,50,0.0159,0.0857,0.185,0.067,0.843,Dy_accu,20.995
11,55,0.0205,0.109,0.188,0.0851,1.09,Dy_accu,20.995
12,60,0.0261,0.138,0.189,0.108,1.38,Dy_accu,20.994
13,65,0.0333,0.175,0.19,0.137,1.77,Dy_accu,20.992
14,70,0.042,0.223,0.189,0.174,2.23,Dy_accu,20.99
15,75,0.0526,0.283,0.186,0.221,2.79,Dy_accu,20.988
16,80,0.0662,0.359,0.184,0.281,3.51,Dy_accu,20.986
17,85,0.0836,0.456,0.184,0.356,4.44,Dy_accu,20.984
18,90,0.105,0.578,0.181,0.452,5.56,Dy_accu,20.983
19,95,0.133,0.734,0.181,0.574,7.04,Dy_accu,20.986
20,100,0.167,0.932,0.18,0.729,8.88,Dy_accu,20.992
21,105,0.211,1.18,0.178,0.925,11.2,Dy_accu,20.998
22,110,0.266,1.5,0.177,1.17,14.1,Dy_accu,21.002
23,115,0.335,1.91,0.176,1.49,17.8,Dy_accu,21.003
24,120,0.419,2.42,0.173,1.89,22.2,Dy_accu,21.003
25,125,0.521,3.07,0.17,2.4,27.7,Dy_accu,21.001
26,130,0.648,3.9,0.166,3.05,34.4,Dy_accu,20.999
27,135,0.803,4.96,0.162,3.87,42.6,Dy_accu,20.996
28,140,0.986,6.29,0.157,4.92,52.3,Dy_accu,20.994
29,145,1.21,7.99,0.151,6.24,64,Dy_accu,20.991
30,150,1.46,10.1,0.144,7.93,77.7,Dy_accu,20.989
31,155,1.77,12.9,0.137,10.1,93.8,Dy_accu,20.988
32,160,2.12,16.3,0.13,12.8,113,Dy_accu,20.99
33,165,2.53,20.7,0.122,16.2,134,Dy_accu,20.995
34,170,3,26.3,0.114,20.6,159,Dy_accu,21.001
35,175,3.54,33.4,0.106,26.1,188,Dy_accu,21.004
36,180,4.15,42.5,0.0978,33.2,220,Dy_accu,21.006
37,185,4.85,53.9,0.09,42.1,257,Dy_accu,21.005
38,190,5.64,68.4,0.0823,53.5,299,Dy_accu,21.003
39,195,6.52,86.9,0.075,67.9,346,Dy_accu,21
40,200,7.52,110,0.0682,86.2,399,Dy_accu,20.998
41,205,8.66,140,0.0619,109,460,Dy_accu,20.996
42,210,10.1,178,0.0566,139,534,Dy_accu,20.992
43,215,11.8,226,0.0521,176,624,Dy_accu,20.99
44,220,13.7,287,0.0477,224,726,Dy_accu,20.99
45,225,15.7,364,0.0432,284,834,Dy_accu,20.994
46,230,18.2,462,0.0394,361,967,Dy_accu,20.999
47,235,21.5,586,0.0366,459,1.14,Dy_accu,21.005
48,240,25.2,744,0.0338,582,1.34,Dy_accu,21.01
49,245,29.3,945,0.031,739,1.55,Dy_accu,21.012
50,250,33.9,1200,0.0283,938,1.8,Dy_accu,21.011
,,,,,,,,
Interval:,,,2,,,,,
Number of Data Points:,,,10,,,,,
,,,,,,,,
Time Setting:,,,"10 Meas. Pts., Reset Strain",,,,,
,,,Meas. Pt. Duration 1 s,,,,,
Measuring Profile:,,,,,,,,
  Shear Rate,,,"d(gamma)/dt = 1,200 1/s",,,,,
,,,,,,,,
Meas. Pts.,Time,Shear Stress,Shear Rate,Viscosity,Speed,Torque,Status,Temperature
,[s],[Pa],[1/s],[Pa·s],[1/min],[µNm],[],[°C]
1,251,33.8,1200,0.0282,938,1.79,Dy_accu,21.012
2,252,33.7,1200,0.0281,938,1.79,Dy_accu,21.011
3,253,33.7,1200,0.0281,938,1.79,Dy_accu,21.011
4,254,33.8,1200,0.0281,938,1.79,Dy_accu,21.011
5,255,33.7,1200,0.028,938,1.79,Dy_accu,21.012
6,256,33.6,1200,0.028,938,1.78,Dy_accu,21.01
7,257,33.7,1200,0.0281,938,1.79,Dy_accu,21.012
8,258,33.7,1200,0.0281,938,1.79,Dy_accu,21.01
9,259,33.7,1200,0.0281,938,1.79,Dy_accu,21.01
10,260,33.6,1200,0.028,938,1.78,Dy_accu,21.009
,,,,,,,,
Interval:,,,3,,,,,
Number of Data Points:,,,50,,,,,
,,,,,,,,
Time Setting:,,,50 Meas. Pts.,,,,,
,,,Meas. Pt. Duration 5 s,,,,,
Measuring Profile:,,,,,,,,
  Shear Rate,,,"d(gamma)/dt = 1,200 ... 0.01 1/s log",,,,,
,,,,,,,,
Meas. Pts.,Time,Shear Stress,Shear Rate,Viscosity,Speed,Torque,Status,Temperature
,[s],[Pa],[1/s],[Pa·s],[1/min],[µNm],[],[°C]
1,265,33.6,1200,0.028,938,1.79,Dy_accu,21.008
2,270,28.9,945,0.0306,739,1.53,Dy_accu,21.007
3,275,24.9,745,0.0334,582,1.32,Dy_accu,21.006
4,280,21.5,586,0.0366,459,1.14,Dy_accu,21.002
5,285,18.5,462,0.0401,361,983,Dy_accu,21
6,290,16,364,0.0439,284,847,Dy_accu,20.998
7,295,13.7,287,0.048,224,730,Dy_accu,20.996
8,300,11.8,226,0.0524,176,628,Dy_accu,20.993
9,305,10.2,178,0.0571,139,539,Dy_accu,20.991
10,310,8.66,140,0.0619,110,460,Dy_accu,20.988
11,315,7.37,110,0.0668,86.2,391,Dy_accu,20.987
12,320,6.26,86.9,0.072,67.9,332,Dy_accu,20.992
13,325,5.3,68.4,0.0774,53.5,281,Dy_accu,20.995
14,330,4.47,53.9,0.083,42.1,237,Dy_accu,21
15,335,3.77,42.5,0.0887,33.2,200,Dy_accu,21.005
16,340,3.16,33.4,0.0945,26.2,168,Dy_accu,21.008
17,345,2.64,26.3,0.1,20.6,140,Dy_accu,21.008
18,350,2.21,20.8,0.106,16.2,117,Dy_accu,21.006
19,355,1.83,16.3,0.112,12.8,97.3,Dy_accu,21.003
20,360,1.52,12.9,0.118,10.1,80.6,Dy_accu,21
21,365,1.25,10.1,0.123,7.93,66.3,Dy_accu,20.997
22,370,1.03,7.99,0.128,6.25,54.5,Dy_accu,20.995
23,375,0.839,6.29,0.133,4.92,44.5,Dy_accu,20.992
24,380,0.685,4.96,0.138,3.87,36.4,Dy_accu,20.988
25,385,0.555,3.9,0.142,3.05,29.5,Dy_accu,20.989
26,390,0.449,3.07,0.146,2.4,23.8,Dy_accu,20.993
27,395,0.362,2.42,0.15,1.89,19.2,Dy_accu,20.998
28,400,0.293,1.91,0.153,1.49,15.5,Dy_accu,21.003
29,405,0.237,1.5,0.157,1.17,12.6,Dy_accu,21.007
30,410,0.19,1.18,0.161,0.925,10.1,Dy_accu,21.008
31,415,0.153,0.932,0.164,0.729,8.12,Dy_accu,21.006
32,420,0.123,0.734,0.167,0.574,6.52,Dy_accu,21.004
33,425,0.0981,0.578,0.17,0.452,5.21,Dy_accu,21.002
34,430,0.079,0.456,0.173,0.356,4.19,Dy_accu,21
35,435,0.0633,0.359,0.176,0.281,3.36,Dy_accu,20.997
36,440,0.0506,0.283,0.179,0.221,2.69,Dy_accu,20.994
37,445,0.0405,0.223,0.182,0.174,2.15,Dy_accu,20.992
38,450,0.0326,0.175,0.186,0.137,1.73,Dy_accu,20.991
39,455,0.026,0.138,0.188,0.108,1.38,Dy_accu,20.994
40,460,0.0209,0.109,0.192,0.0851,1.11,Dy_accu,20.998
41,465,0.0165,0.0857,0.193,0.067,0.878,Dy_accu,21.004
42,470,0.0132,0.0675,0.196,0.0528,0.703,Dy_accu,21.007
43,475,0.0105,0.0532,0.197,0.0416,0.556,Dy_accu,21.009
44,480,0.00841,0.0419,0.201,0.0327,0.446,Dy_accu,21.009
45,485,0.0065,0.033,0.197,0.0258,0.345,Dy_accu,21.006
46,490,0.00493,0.026,0.19,0.0203,0.262,Dy_accu,21.003
47,495,0.00391,0.0205,0.191,0.016,0.207,Dy_accu,21.001
48,500,0.00304,0.0161,0.189,0.0126,0.161,Dy_accu,20.998
49,505,0.00234,0.0127,0.184,0.00993,0.124,Dy_accu,20.995
50,510,0.00173,0.01,0.173,0.00782,0.0919,Dy_accu,20.992
,,,,,,,,
Data Series Information,,,,,,,,
Name:,,,Scatter study - HFC - PAC4 2nd batch - 6,,,,,
Sample:,,,"Dist. H2O + 4 g/L PAC, 2nd batch",,,,,
Operator:,,,Alex,,,,,
Remarks:,,,Bergen,,,,,
Number of Intervals:,,,3,,,,,
Application:,,,RHEOPLUS/32 V3.61 21006089-33024,,,,,
Device:,,,"MCR102 SN81115860; FW3.86; Slot(4,-1); Adj(69,0)d",,,,,
Measuring Date/Time:,,,08/07/2015; 20:30 PM,,,,,
Measuring System:,,,CC27-SN26350; d=0 mm,,,,,
Accessories:,,,TU1=C-PTD200-SN81077144,,,,,
,,,,,,,,
Calculating Constants:,,,,,,,,
- Csr [min/s]:,,,12.789.756,,,,,
- Css [Pa/mNm]:,,,18.841.121,,,,,
- Start Delay Time [s]:,,,7.459,,,,,
- Substance Density [rho]:,,,1,,,,,
- Measurement Type:,,,2,,,,,
- Axial Compliance [m/N]:,,,1.00E-06,,,,,
- Position [m]:,,,1.00E-06,,,,,
,,,,,,,,
Interval:,,,1,,,,,
Number of Data Points:,,,50,,,,,
,,,,,,,,
Time Setting:,,,50 Meas. Pts.,,,,,
,,,Meas. Pt. Duration 5 s,,,,,
Measuring Profile:,,,,,,,,
  Shear Rate,,,"d(gamma)/dt = 0.01 ... 1,200 1/s log",,,,,
,,,,,,,,
Meas. Pts.,Time,Shear Stress,Shear Rate,Viscosity,Speed,Torque,Status,Temperature
,[s],[Pa],[1/s],[Pa·s],[1/min],[µNm],[],[°C]
1,5,0.00228,0.00999,0.228,0.00781,0.121,Dy_accu,20.967
2,10,0.00287,0.0127,0.226,0.00993,0.152,Dy_accu,20.968
3,15,0.00358,0.0161,0.222,0.0126,0.19,Dy_accu,20.969
4,20,0.00451,0.0205,0.22,0.016,0.239,Dy_accu,20.968
5,25,0.00574,0.026,0.221,0.0203,0.304,Dy_accu,20.969
6,30,0.00708,0.033,0.215,0.0258,0.376,Dy_accu,20.969
7,35,0.00866,0.0419,0.207,0.0327,0.46,Dy_accu,20.972
8,40,0.011,0.0532,0.207,0.0416,0.585,Dy_accu,20.979
9,45,0.0139,0.0675,0.206,0.0528,0.738,Dy_accu,20.986
10,50,0.0175,0.0857,0.205,0.067,0.931,Dy_accu,20.992
11,55,0.0219,0.109,0.201,0.0851,1.16,Dy_accu,20.992
12,60,0.0276,0.138,0.2,0.108,1.47,Dy_accu,20.993
13,65,0.0346,0.175,0.197,0.137,1.84,Dy_accu,20.993
14,70,0.0434,0.223,0.195,0.174,2.3,Dy_accu,20.994
15,75,0.0539,0.283,0.191,0.221,2.86,Dy_accu,20.994
16,80,0.0668,0.359,0.186,0.281,3.55,Dy_accu,20.994
17,85,0.0832,0.456,0.183,0.356,4.42,Dy_accu,20.992
18,90,0.105,0.578,0.181,0.452,5.56,Dy_accu,20.991
19,95,0.132,0.734,0.18,0.574,7,Dy_accu,20.99
20,100,0.166,0.932,0.178,0.729,8.8,Dy_accu,20.988
21,105,0.209,1.18,0.177,0.925,11.1,Dy_accu,20.988
22,110,0.264,1.5,0.176,1.17,14,Dy_accu,20.986
23,115,0.333,1.91,0.174,1.49,17.7,Dy_accu,20.985
24,120,0.418,2.42,0.173,1.89,22.2,Dy_accu,20.984
25,125,0.522,3.07,0.17,2.4,27.7,Dy_accu,20.986
26,130,0.647,3.9,0.166,3.05,34.3,Dy_accu,20.991
27,135,0.799,4.96,0.161,3.87,42.4,Dy_accu,20.997
28,140,0.984,6.29,0.156,4.92,52.2,Dy_accu,21.001
29,145,1.2,7.99,0.151,6.24,63.8,Dy_accu,21.002
30,150,1.46,10.1,0.144,7.93,77.5,Dy_accu,21.001
31,155,1.76,12.9,0.137,10.1,93.7,Dy_accu,21
32,160,2.12,16.3,0.129,12.8,112,Dy_accu,21
33,165,2.53,20.7,0.122,16.2,134,Dy_accu,20.997
34,170,3,26.3,0.114,20.6,159,Dy_accu,20.995
35,175,3.53,33.4,0.106,26.1,188,Dy_accu,20.994
36,180,4.14,42.5,0.0976,33.2,220,Dy_accu,20.992
37,185,4.83,53.9,0.0897,42.1,257,Dy_accu,20.991
38,190,5.62,68.4,0.0822,53.5,298,Dy_accu,20.99
39,195,6.5,86.9,0.0748,67.9,345,Dy_accu,20.99
40,200,7.5,110,0.068,86.2,398,Dy_accu,20.993
41,205,8.64,140,0.0617,109,459,Dy_accu,20.998
42,210,10,178,0.0564,139,532,Dy_accu,21.004
43,215,11.7,226,0.0519,176,621,Dy_accu,21.007
44,220,13.7,287,0.0478,224,726,Dy_accu,21.009
45,225,15.7,364,0.0432,284,834,Dy_accu,21.009
46,230,18.3,462,0.0396,361,971,Dy_accu,21.009
47,235,21.7,586,0.0369,459,1.15,Dy_accu,21.008
48,240,25.2,744,0.0338,582,1.34,Dy_accu,21.008
49,245,29.1,945,0.0308,739,1.55,Dy_accu,21.006
50,250,33.8,1200,0.0282,938,1.8,Dy_accu,21.006
,,,,,,,,
Interval:,,,2,,,,,
Number of Data Points:,,,10,,,,,
,,,,,,,,
Time Setting:,,,"10 Meas. Pts., Reset Strain",,,,,
,,,Meas. Pt. Duration 1 s,,,,,
Measuring Profile:,,,,,,,,
  Shear Rate,,,"d(gamma)/dt = 1,200 1/s",,,,,
,,,,,,,,
Meas. Pts.,Time,Shear Stress,Shear Rate,Viscosity,Speed,Torque,Status,Temperature
,[s],[Pa],[1/s],[Pa·s],[1/min],[µNm],[],[°C]
[...]
42,210,9.92,178,0.0558,139,527,Dy_accu,21.001
43,215,11.5,226,0.051,176,611,Dy_accu,20.999
44,220,13.3,287,0.0465,224,708,Dy_accu,20.996
45,225,15.3,364,0.0422,284,814,Dy_accu,20.995
46,230,17.9,462,0.0387,361,949,Dy_accu,20.995
47,235,21,586,0.0358,459,1.11,Dy_accu,20.998
48,240,24.6,744,0.033,582,1.31,Dy_accu,21
49,245,28.4,945,0.0301,739,1.51,Dy_accu,21.003
50,250,32.9,1200,0.0274,938,1.75,Dy_accu,21.005
,,,,,,,,
Interval:,,,2,,,,,
Number of Data Points:,,,10,,,,,
,,,,,,,,
Time Setting:,,,"10 Meas. Pts., Reset Strain",,,,,
,,,Meas. Pt. Duration 1 s,,,,,
Measuring Profile:,,,,,,,,
  Shear Rate,,,"d(gamma)/dt = 1,200 1/s",,,,,
,,,,,,,,
Meas. Pts.,Time,Shear Stress,Shear Rate,Viscosity,Speed,Torque,Status,Temperature
,[s],[Pa],[1/s],[Pa·s],[1/min],[µNm],[],[°C]
1,251,32.9,1200,0.0274,938,1.75,Dy_accu,21.004
2,252,32.8,1200,0.0273,938,1.74,Dy_accu,21.005
3,253,32.9,1200,0.0274,938,1.74,Dy_accu,21.006
4,254,32.9,1200,0.0274,938,1.75,Dy_accu,21.004
5,255,32.9,1200,0.0274,938,1.75,Dy_accu,21.004
6,256,32.8,1200,0.0273,938,1.74,Dy_accu,21.005
7,257,32.9,1200,0.0274,938,1.74,Dy_accu,21.004
8,258,32.8,1200,0.0274,938,1.74,Dy_accu,21.006
9,259,32.8,1200,0.0273,938,1.74,Dy_accu,21.004
10,260,32.9,1200,0.0274,938,1.74,Dy_accu,21.003
,,,,,,,,
Interval:,,,3,,,,,
Number of Data Points:,,,50,,,,,
,,,,,,,,
Time Setting:,,,50 Meas. Pts.,,,,,
,,,Meas. Pt. Duration 5 s,,,,,
Measuring Profile:,,,,,,,,
  Shear Rate,,,"d(gamma)/dt = 1,200 ... 0.01 1/s log",,,,,
,,,,,,,,
Meas. Pts.,Time,Shear Stress,Shear Rate,Viscosity,Speed,Torque,Status,Temperature
,[s],[Pa],[1/s],[Pa·s],[1/min],[µNm],[],[°C]
1,265,32.7,1200,0.0273,938,1.74,Dy_accu,21.002
2,270,28.1,945,0.0297,739,1.49,Dy_accu,21.001
3,275,24.2,745,0.0325,582,1.28,Dy_accu,20.999
4,280,20.9,586,0.0356,459,1.11,Dy_accu,20.996
5,285,18,462,0.0389,361,955,Dy_accu,20.995
6,290,15.5,364,0.0427,284,825,Dy_accu,20.994
7,295,13.4,287,0.0468,224,711,Dy_accu,20.995
8,300,11.5,226,0.0509,176,610,Dy_accu,20.998
9,305,9.84,178,0.0554,139,523,Dy_accu,21
10,310,8.38,140,0.0598,110,445,Dy_accu,21.004
11,315,7.1,110,0.0644,86.2,377,Dy_accu,21.005
12,320,6.01,86.9,0.0691,67.9,319,Dy_accu,21.006
13,325,5.07,68.4,0.0741,53.5,269,Dy_accu,21.005
14,330,4.27,53.9,0.0792,42.1,227,Dy_accu,21.003
15,335,3.59,42.5,0.0845,33.2,190,Dy_accu,20.999
16,340,3.01,33.4,0.0899,26.2,160,Dy_accu,20.996
17,345,2.51,26.3,0.0953,20.6,133,Dy_accu,20.994
18,350,2.09,20.8,0.101,16.2,111,Dy_accu,20.993
19,355,1.73,16.3,0.106,12.8,92,Dy_accu,20.995
20,360,1.43,12.9,0.111,10.1,76.1,Dy_accu,20.997
21,365,1.18,10.1,0.116,7.93,62.7,Dy_accu,20.999
22,370,0.967,7.99,0.121,6.25,51.3,Dy_accu,21.003
23,375,0.791,6.29,0.126,4.92,42,Dy_accu,21.006
24,380,0.644,4.96,0.13,3.87,34.2,Dy_accu,21.006
25,385,0.522,3.9,0.134,3.05,27.7,Dy_accu,21.005
26,390,0.423,3.07,0.138,2.4,22.5,Dy_accu,21.002
27,395,0.343,2.42,0.142,1.89,18.2,Dy_accu,20.999
28,400,0.277,1.91,0.145,1.49,14.7,Dy_accu,20.996
29,405,0.221,1.5,0.147,1.17,11.7,Dy_accu,20.994
30,410,0.179,1.18,0.151,0.925,9.48,Dy_accu,20.994
31,415,0.142,0.932,0.152,0.729,7.54,Dy_accu,20.995
32,420,0.114,0.734,0.155,0.574,6.05,Dy_accu,20.997
33,425,0.0915,0.578,0.158,0.452,4.86,Dy_accu,21
34,430,0.0734,0.456,0.161,0.356,3.89,Dy_accu,21.004
35,435,0.058,0.359,0.162,0.281,3.08,Dy_accu,21.005
36,440,0.0456,0.283,0.161,0.221,2.42,Dy_accu,21.006
37,445,0.0359,0.223,0.161,0.174,1.91,Dy_accu,21.003
38,450,0.0286,0.175,0.163,0.137,1.52,Dy_accu,21.001
39,455,0.0226,0.138,0.164,0.108,1.2,Dy_accu,20.998
40,460,0.0181,0.109,0.166,0.0851,0.959,Dy_accu,20.994
41,465,0.0143,0.0857,0.167,0.067,0.761,Dy_accu,20.994
42,470,0.0114,0.0675,0.169,0.0528,0.607,Dy_accu,20.996
43,475,0.00868,0.0532,0.163,0.0416,0.46,Dy_accu,20.998
44,480,0.00667,0.0419,0.159,0.0327,0.354,Dy_accu,21
45,485,0.00517,0.033,0.157,0.0258,0.274,Dy_accu,21.002
46,490,0.00393,0.026,0.151,0.0203,0.208,Dy_accu,21.006
47,495,0.00301,0.0205,0.147,0.016,0.16,Dy_accu,21.006
48,500,0.00214,0.0161,0.133,0.0126,0.114,Dy_accu,21.005
49,505,0.00151,0.0127,0.119,0.00993,0.0803,Dy_accu,21.003
50,510,0.00102,0.01,0.102,0.00782,0.054,Dy_accu,21
,,,,,,,,
Data Series Information,,,,,,,,
Name:,,,Scatter study - HFC - PAC4 2nd batch - 13,,,,,
Sample:,,,"Dist. H2O + 4 g/L PAC, 2nd batch",,,,,
Operator:,,,Alex,,,,,
Remarks:,,,Bergen,,,,,
Number of Intervals:,,,3,,,,,
Application:,,,RHEOPLUS/32 V3.61 21006089-33024,,,,,
Device:,,,"MCR102 SN81115860; FW3.86; Slot(4,-1); Adj(69,0)d",,,,,
Measuring Date/Time:,,,09/07/2015; 09:23 PM,,,,,
Measuring System:,,,CC27-SN26350; d=0 mm,,,,,
Accessories:,,,TU1=C-PTD200-SN81077144,,,,,
,,,,,,,,
Calculating Constants:,,,,,,,,
- Csr [min/s]:,,,12.789.756,,,,,
- Css [Pa/mNm]:,,,18.841.121,,,,,
- Start Delay Time [s]:,,,7.215,,,,,
- Substance Density [rho]:,,,1,,,,,
- Measurement Type:,,,2,,,,,
- Axial Compliance [m/N]:,,,1.00E-06,,,,,
- Position [m]:,,,1.00E-06,,,,,
,,,,,,,,
Interval:,,,1,,,,,
Number of Data Points:,,,50,,,,,
,,,,,,,,
Time Setting:,,,50 Meas. Pts.,,,,,
,,,Meas. Pt. Duration 5 s,,,,,
Measuring Profile:,,,,,,,,
  Shear Rate,,,"d(gamma)/dt = 0.01 ... 1,200 1/s log",,,,,
,,,,,,,,
Meas. Pts.,Time,Shear Stress,Shear Rate,Viscosity,Speed,Torque,Status,Temperature
,[s],[Pa],[1/s],[Pa·s],[1/min],[µNm],[],[°C]
1,5,0.00271,0.00999,0.272,0.00781,0.144,Dy_accu,20.988
2,10,0.00329,0.0127,0.259,0.00993,0.175,Dy_accu,20.988
3,15,0.00403,0.0161,0.25,0.0126,0.214,Dy_accu,20.987
4,20,0.00499,0.0205,0.244,0.016,0.265,Dy_accu,20.985
5,25,0.00614,0.026,0.236,0.0203,0.326,Dy_accu,20.984
6,30,0.00752,0.033,0.228,0.0258,0.399,Dy_accu,20.983
7,35,0.00927,0.0419,0.221,0.0327,0.492,Dy_accu,20.982
8,40,0.0116,0.0532,0.218,0.0416,0.616,Dy_accu,20.982
9,45,0.0143,0.0675,0.212,0.0528,0.758,Dy_accu,20.986
10,50,0.0179,0.0857,0.209,0.067,0.952,Dy_accu,20.991
11,55,0.0228,0.109,0.21,0.0851,1.21,Dy_accu,20.995
12,60,0.0286,0.138,0.207,0.108,1.52,Dy_accu,20.997
13,65,0.036,0.175,0.206,0.137,1.91,Dy_accu,20.997
14,70,0.0449,0.223,0.202,0.174,2.38,Dy_accu,20.996
15,75,0.056,0.283,0.198,0.221,2.97,Dy_accu,20.995
16,80,0.0698,0.359,0.195,0.281,3.7,Dy_accu,20.994
17,85,0.0878,0.456,0.193,0.356,4.66,Dy_accu,20.992
18,90,0.11,0.578,0.19,0.452,5.83,Dy_accu,20.991
19,95,0.137,0.734,0.187,0.574,7.3,Dy_accu,20.989
20,100,0.173,0.932,0.185,0.729,9.18,Dy_accu,20.989
21,105,0.217,1.18,0.183,0.925,11.5,Dy_accu,20.991
22,110,0.272,1.5,0.181,1.17,14.4,Dy_accu,20.994
23,115,0.341,1.91,0.179,1.49,18.1,Dy_accu,20.998
24,120,0.428,2.42,0.177,1.89,22.7,Dy_accu,21.001
25,125,0.533,3.07,0.173,2.4,28.3,Dy_accu,21.001
26,130,0.662,3.9,0.17,3.05,35.1,Dy_accu,21.002
27,135,0.814,4.96,0.164,3.87,43.2,Dy_accu,21.001
28,140,0.998,6.29,0.159,4.92,53,Dy_accu,20.999
29,145,1.22,7.99,0.152,6.24,64.6,Dy_accu,20.997
30,150,1.48,10.1,0.146,7.93,78.5,Dy_accu,20.994
31,155,1.78,12.9,0.138,10.1,94.6,Dy_accu,20.994
32,160,2.14,16.3,0.131,12.8,113,Dy_accu,20.992
33,165,2.55,20.7,0.123,16.2,135,Dy_accu,20.993
34,170,3.02,26.3,0.115,20.6,160,Dy_accu,20.996
35,175,3.57,33.4,0.107,26.1,189,Dy_accu,20.999
36,180,4.19,42.5,0.0986,33.2,222,Dy_accu,21.002
37,185,4.89,53.9,0.0907,42.1,259,Dy_accu,21.004
38,190,5.69,68.4,0.0831,53.5,302,Dy_accu,21.004
39,195,6.59,86.9,0.0758,67.9,350,Dy_accu,21.002
40,200,7.59,110,0.0688,86.2,403,Dy_accu,21.001
41,205,8.75,140,0.0625,109,465,Dy_accu,20.997
42,210,10.2,178,0.0571,139,539,Dy_accu,20.995
43,215,11.8,226,0.0523,176,627,Dy_accu,20.994
44,220,13.7,287,0.0479,224,728,Dy_accu,20.994
45,225,15.7,364,0.0432,284,834,Dy_accu,20.995
46,230,18.3,462,0.0397,361,973,Dy_accu,20.997
47,235,21.5,586,0.0367,459,1.14,Dy_accu,21.002
48,240,25.2,744,0.0338,582,1.34,Dy_accu,21.005
49,245,29.1,945,0.0308,739,1.54,Dy_accu,21.006
50,250,33.8,1200,0.0281,938,1.79,Dy_accu,21.005
,,,,,,,,
Interval:,,,2,,,,,
Number of Data Points:,,,10,,,,,
,,,,,,,,
Time Setting:,,,"10 Meas. Pts., Reset Strain",,,,,
,,,Meas. Pt. Duration 1 s,,,,,
Measuring Profile:,,,,,,,,
  Shear Rate,,,"d(gamma)/dt = 1,200 1/s",,,,,
,,,,,,,,
Meas. Pts.,Time,Shear Stress,Shear Rate,Viscosity,Speed,Torque,Status,Temperature
,[s],[Pa],[1/s],[Pa·s],[1/min],[µNm],[],[°C]
1,251,33.6,1200,0.028,938,1.79,Dy_accu,21.004
2,252,33.6,1200,0.028,938,1.79,Dy_accu,21.005
3,253,33.6,1200,0.028,938,1.78,Dy_accu,21.004
4,254,33.6,1200,0.028,938,1.78,Dy_accu,21.003
5,255,33.6,1200,0.028,938,1.78,Dy_accu,21.004
6,256,33.6,1200,0.028,938,1.78,Dy_accu,21.003
7,257,33.6,1200,0.028,938,1.78,Dy_accu,21.003
8,258,33.5,1200,0.0279,938,1.78,Dy_accu,21.002
9,259,33.5,1200,0.0279,938,1.78,Dy_accu,21.002
10,260,33.5,1200,0.0279,938,1.78,Dy_accu,21.001
,,,,,,,,
Interval:,,,3,,,,,
Number of Data Points:,,,50,,,,,
,,,,,,,,
Time Setting:,,,50 Meas. Pts.,,,,,
,,,Meas. Pt. Duration 5 s,,,,,
Measuring Profile:,,,,,,,,
  Shear Rate,,,"d(gamma)/dt = 1,200 ... 0.01 1/s log",,,,,
,,,,,,,,
Meas. Pts.,Time,Shear Stress,Shear Rate,Viscosity,Speed,Torque,Status,Temperature
,[s],[Pa],[1/s],[Pa·s],[1/min],[µNm],[],[°C]
1,265,33.6,1200,0.028,938,1.78,Dy_accu,21
2,270,28.8,945,0.0305,739,1.53,Dy_accu,21
3,275,24.9,745,0.0334,582,1.32,Dy_accu,20.997
4,280,21.4,586,0.0366,459,1.14,Dy_accu,20.995
5,285,18.5,462,0.0401,361,983,Dy_accu,20.993
6,290,16,364,0.044,284,850,Dy_accu,20.993
7,295,13.8,287,0.0482,224,733,Dy_accu,20.995
8,300,11.9,226,0.0526,176,630,Dy_accu,20.998
9,305,10.2,178,0.0572,139,540,Dy_accu,21.002
10,310,8.65,140,0.0618,110,459,Dy_accu,21.003
11,315,7.34,110,0.0666,86.2,390,Dy_accu,21.004
12,320,6.21,86.9,0.0715,67.9,330,Dy_accu,21.001
13,325,5.25,68.4,0.0767,53.5,278,Dy_accu,21
14,330,4.42,53.9,0.082,42.1,235,Dy_accu,20.998
15,335,3.72,42.5,0.0875,33.2,197,Dy_accu,20.994
16,340,3.12,33.4,0.0933,26.2,166,Dy_accu,20.991
17,345,2.61,26.3,0.0991,20.6,139,Dy_accu,20.991
18,350,2.17,20.8,0.105,16.2,115,Dy_accu,20.992
19,355,1.81,16.3,0.11,12.8,95.8,Dy_accu,20.995
20,360,1.49,12.9,0.116,10.1,79.3,Dy_accu,20.998
21,365,1.23,10.1,0.121,7.93,65.3,Dy_accu,21.001
22,370,1.01,7.99,0.126,6.24,53.6,Dy_accu,21.002
23,375,0.827,6.29,0.131,4.92,43.9,Dy_accu,21.004
24,380,0.672,4.96,0.136,3.87,35.7,Dy_accu,21.004
25,385,0.546,3.9,0.14,3.05,29,Dy_accu,21.003
26,390,0.444,3.07,0.144,2.4,23.5,Dy_accu,20.999
27,395,0.358,2.42,0.148,1.89,19,Dy_accu,20.995
28,400,0.288,1.91,0.151,1.49,15.3,Dy_accu,20.994
29,405,0.231,1.5,0.154,1.17,12.3,Dy_accu,20.993
30,410,0.185,1.18,0.157,0.925,9.84,Dy_accu,20.994
31,415,0.149,0.932,0.16,0.729,7.9,Dy_accu,20.997
32,420,0.119,0.734,0.163,0.574,6.34,Dy_accu,20.999
33,425,0.0957,0.578,0.165,0.452,5.08,Dy_accu,21.001
34,430,0.0763,0.456,0.167,0.356,4.05,Dy_accu,21.003
35,435,0.0613,0.359,0.171,0.281,3.25,Dy_accu,21.004
36,440,0.0492,0.283,0.174,0.221,2.61,Dy_accu,21.005
37,445,0.0392,0.223,0.176,0.174,2.08,Dy_accu,21.003
38,450,0.0315,0.175,0.18,0.137,1.67,Dy_accu,21
39,455,0.025,0.138,0.181,0.108,1.33,Dy_accu,20.996
40,460,0.0202,0.109,0.186,0.0851,1.07,Dy_accu,20.993
41,465,0.0163,0.0857,0.19,0.067,0.863,Dy_accu,20.992
42,470,0.0131,0.0675,0.194,0.0528,0.696,Dy_accu,20.993
43,475,0.0103,0.0532,0.194,0.0416,0.548,Dy_accu,20.994
44,480,0.00834,0.0419,0.199,0.0327,0.443,Dy_accu,20.994
45,485,0.00674,0.033,0.204,0.0258,0.358,Dy_accu,20.998
46,490,0.00541,0.026,0.208,0.0203,0.287,Dy_accu,21
47,495,0.0042,0.0205,0.205,0.016,0.223,Dy_accu,21.001
48,500,0.00337,0.0161,0.209,0.0126,0.179,Dy_accu,21.003
49,505,0.00272,0.0127,0.214,0.00993,0.144,Dy_accu,21.005
50,510,0.00218,0.01,0.218,0.00782,0.116,Dy_accu,21.005
,,,,,,,,
Data Series Information,,,,,,,,
Name:,,,Scatter study - HFC - PAC4 2nd batch - same sample as previous 1,,,,,
Sample:,,,"Dist. H2O + 4 g/L PAC, 2nd batch",,,,,
Operator:,,,Alex,,,,,
Remarks:,,,"Bergen, same sample as previous, time in rheometer 30s",,,,,
Number of Intervals:,,,1,,,,,
Application:,,,RHEOPLUS/32 V3.61 21006089-33024,,,,,
Device:,,,"MCR102 SN81115860; FW3.86; Slot(4,-1); Adj(69,0)d",,,,,
Measuring Date/Time:,,,09/07/2015; 09:33 PM,,,,,
Measuring System:,,,CC27-SN26350; d=0 mm,,,,,
Accessories:,,,TU1=C-PTD200-SN81077144,,,,,
,,,,,,,,
Calculating Constants:,,,,,,,,
- Csr [min/s]:,,,12.789.756,,,,,
- Css [Pa/mNm]:,,,18.841.121,,,,,
- Start Delay Time [s]:,,,8.732,,,,,
- Substance Density [rho]:,,,1,,,,,
- Measurement Type:,,,2,,,,,
- Axial Compliance [m/N]:,,,1.00E-06,,,,,
- Position [m]:,,,1.00E-06,,,,,
,,,,,,,,
Interval:,,,1,,,,,
Number of Data Points:,,,4,,,,,
,,,,,,,,
Time Setting:,,,50 Meas. Pts.,,,,,
,,,Meas. Pt. Duration 5 s,,,,,
Measuring Profile:,,,,,,,,
  Shear Rate,,,"d(gamma)/dt = 0.01 ... 1,200 1/s log",,,,,
,,,,,,,,
Meas. Pts.,Time,Shear Stress,Shear Rate,Viscosity,Speed,Torque,Status,Temperature
,[s],[Pa],[1/s],[Pa·s],[1/min],[µNm],[],[°C]
1,5,0.00232,0.01,0.232,0.00782,0.123,Dy_accu,20.641
2,10,0.00262,0.0127,0.206,0.00993,0.139,Dy_accu,20.608
3,15,0.0032,0.0161,0.199,0.0126,0.17,Dy_accu,20.57
4,20,0.00401,0.0205,0.196,0.016,0.213,Dy_accu,20.53
,,,,,,,,
Data Series Information,,,,,,,,
Name:,,,Scatter study - HFC - PAC4 2nd batch - same sample as previous 2,,,,,
Sample:,,,"Dist. H2O + 4 g/L PAC, 2nd batch",,,,,
Operator:,,,Alex,,,,,
Remarks:,,,"Bergen, same sample as previous, time in rheometer 11 min",,,,,
Number of Intervals:,,,3,,,,,
Application:,,,RHEOPLUS/32 V3.61 21006089-33024,,,,,
Device:,,,"MCR102 SN81115860; FW3.86; Slot(4,-1); Adj(70,0)d",,,,,
Measuring Date/Time:,,,09/07/2015; 09:45 PM,,,,,
Measuring System:,,,CC27-SN26350; d=0 mm,,,,,
Accessories:,,,TU1=C-PTD200-SN81077144,,,,,
,,,,,,,,
Calculating Constants:,,,,,,,,
- Csr [min/s]:,,,12.789.756,,,,,
- Css [Pa/mNm]:,,,18.841.121,,,,,
- Start Delay Time [s]:,,,7.437,,,,,
- Substance Density [rho]:,,,1,,,,,
- Measurement Type:,,,2,,,,,
- Axial Compliance [m/N]:,,,1.00E-06,,,,,
- Position [m]:,,,1.00E-06,,,,,
,,,,,,,,
Interval:,,,1,,,,,
Number of Data Points:,,,50,,,,,
,,,,,,,,
Time Setting:,,,50 Meas. Pts.,,,,,
,,,Meas. Pt. Duration 5 s,,,,,
Measuring Profile:,,,,,,,,
  Shear Rate,,,"d(gamma)/dt = 0.01 ... 1,200 1/s log",,,,,
,,,,,,,,
Meas. Pts.,Time,Shear Stress,Shear Rate,Viscosity,Speed,Torque,Status,Temperature
,[s],[Pa],[1/s],[Pa·s],[1/min],[µNm],[],[°C]
1,5,0.000599,0.01,0.0599,0.00782,0.0318,"M- ,Dy_",20.993
2,10,0.00139,0.0127,0.11,0.00993,0.0738,Dy_accu,20.993
3,15,0.00206,0.0161,0.128,0.0126,0.109,Dy_accu,20.995
4,20,0.00282,0.0205,0.138,0.016,0.15,Dy_accu,20.996
5,25,0.00376,0.026,0.145,0.0203,0.2,Dy_accu,20.997
6,30,0.00507,0.033,0.154,0.0258,0.269,Dy_accu,20.998
7,35,0.00663,0.0419,0.158,0.0327,0.352,Dy_accu,20.998
8,40,0.00853,0.0532,0.16,0.0416,0.453,Dy_accu,21
9,45,0.011,0.0675,0.163,0.0528,0.583,Dy_accu,21
10,50,0.0143,0.0857,0.167,0.067,0.759,Dy_accu,21
11,55,0.0186,0.109,0.171,0.085,0.988,Dy_accu,21.001
12,60,0.0235,0.138,0.17,0.108,1.25,Dy_accu,21.003
13,65,0.0303,0.175,0.173,0.137,1.61,Dy_accu,21.002
14,70,0.0381,0.223,0.171,0.174,2.02,Dy_accu,21.003
15,75,0.048,0.283,0.17,0.221,2.55,Dy_accu,21.003
16,80,0.06,0.359,0.167,0.281,3.19,Dy_accu,21.004
17,85,0.076,0.456,0.167,0.356,4.03,Dy_accu,21.005
18,90,0.0958,0.578,0.166,0.452,5.08,Dy_accu,21.006
19,95,0.12,0.734,0.164,0.574,6.39,Dy_accu,21.006
20,100,0.152,0.932,0.163,0.729,8.05,Dy_accu,21.007
21,105,0.191,1.18,0.162,0.925,10.2,Dy_accu,21.007
22,110,0.24,1.5,0.16,1.17,12.8,Dy_accu,21.009
23,115,0.301,1.91,0.158,1.49,16,Dy_accu,21.009
24,120,0.376,2.42,0.155,1.89,19.9,Dy_accu,21.011
25,125,0.467,3.07,0.152,2.4,24.8,Dy_accu,21.011
26,130,0.581,3.9,0.149,3.05,30.8,Dy_accu,21.012
27,135,0.72,4.96,0.145,3.87,38.2,Dy_accu,21.013
28,140,0.885,6.29,0.141,4.92,47,Dy_accu,21.015
29,145,1.09,7.99,0.136,6.24,57.7,Dy_accu,21.014
30,150,1.32,10.1,0.13,7.93,70.2,Dy_accu,21.015
31,155,1.61,12.9,0.125,10.1,85.2,Dy_accu,21.016
32,160,1.93,16.3,0.118,12.8,103,Dy_accu,21.016
33,165,2.32,20.7,0.112,16.2,123,Dy_accu,21.014
34,170,2.76,26.3,0.105,20.6,146,Dy_accu,21.011
35,175,3.27,33.4,0.0976,26.1,173,Dy_accu,21.006
36,180,3.85,42.5,0.0907,33.2,205,Dy_accu,21.002
37,185,4.54,53.9,0.0841,42.1,241,Dy_accu,21.001
38,190,5.32,68.4,0.0777,53.5,282,Dy_accu,21
39,195,6.22,86.9,0.0715,67.9,330,Dy_accu,20.998
40,200,7.22,110,0.0655,86.2,383,Dy_accu,20.999
41,205,8.35,140,0.0596,109,443,Dy_accu,20.999
42,210,9.76,178,0.0549,139,518,Dy_accu,21
43,215,11.4,226,0.0504,176,603,Dy_accu,21
44,220,13.2,287,0.0459,224,698,Dy_accu,21.001
45,225,15.2,364,0.0419,284,808,Dy_accu,21.002
46,230,17.6,462,0.0381,361,935,Dy_accu,21.002
47,235,20.6,586,0.0351,459,1.09,Dy_accu,21.003
48,240,24.1,744,0.0323,582,1.28,Dy_accu,21.003
49,245,27.9,945,0.0295,739,1.48,Dy_accu,21.005
50,250,32.4,1200,0.027,938,1.72,Dy_accu,21.006
,,,,,,,,
Interval:,,,2,,,,,
Number of Data Points:,,,10,,,,,
,,,,,,,,
Time Setting:,,,"10 Meas. Pts., Reset Strain",,,,,
,,,Meas. Pt. Duration 1 s,,,,,
Measuring Profile:,,,,,,,,
  Shear Rate,,,"d(gamma)/dt = 1,200 1/s",,,,,
,,,,,,,,
Meas. Pts.,Time,Shear Stress,Shear Rate,Viscosity,Speed,Torque,Status,Temperature
,[s],[Pa],[1/s],[Pa·s],[1/min],[µNm],[],[°C]
1,251,32.3,1200,0.0269,938,1.71,Dy_accu,21.005
2,252,32.2,1200,0.0269,938,1.71,Dy_accu,21.006
3,253,32.1,1200,0.0268,938,1.71,Dy_accu,21.006
4,254,32.3,1200,0.0269,938,1.71,Dy_accu,21.005
5,255,32.2,1200,0.0269,938,1.71,Dy_accu,21.006
6,256,32.1,1200,0.0268,938,1.7,Dy_accu,21.006
7,257,32.2,1200,0.0268,938,1.71,Dy_accu,21.008
8,258,32.3,1200,0.0269,938,1.71,Dy_accu,21.007
9,259,32.2,1200,0.0269,938,1.71,Dy_accu,21.007
10,260,32.1,1200,0.0268,938,1.71,Dy_accu,21.009
,,,,,,,,
Interval:,,,3,,,,,
Number of Data Points:,,,50,,,,,
,,,,,,,,
Time Setting:,,,50 Meas. Pts.,,,,,
,,,Meas. Pt. Duration 5 s,,,,,
Measuring Profile:,,,,,,,,
  Shear Rate,,,"d(gamma)/dt = 1,200 ... 0.01 1/s log",,,,,
,,,,,,,,
Meas. Pts.,Time,Shear Stress,Shear Rate,Viscosity,Speed,Torque,Status,Temperature
,[s],[Pa],[1/s],[Pa·s],[1/min],[µNm],[],[°C]
1,265,32.2,1200,0.0268,938,1.71,Dy_accu,21.009
2,270,27.6,945,0.0292,739,1.47,Dy_accu,21.009
3,275,23.8,745,0.0319,582,1.26,Dy_accu,21.009
4,280,20.5,586,0.0349,459,1.09,Dy_accu,21.006
5,285,17.7,462,0.0383,361,939,Dy_accu,21.002
6,290,15.3,364,0.0421,284,813,Dy_accu,20.998
7,295,13.2,287,0.0462,224,702,Dy_accu,20.996
8,300,11.4,226,0.0504,176,604,Dy_accu,20.996
9,305,9.74,178,0.0548,139,517,Dy_accu,20.996
10,310,8.27,140,0.059,110,439,Dy_accu,20.997
11,315,6.99,110,0.0633,86.2,371,Dy_accu,20.997
12,320,5.89,86.9,0.0678,67.9,313,Dy_accu,20.999
13,325,4.96,68.4,0.0725,53.5,263,Dy_accu,21
14,330,4.16,53.9,0.0772,42.1,221,Dy_accu,21.001
15,335,3.49,42.5,0.0821,33.2,185,Dy_accu,21.002
16,340,2.91,33.4,0.0871,26.2,155,Dy_accu,21.002
17,345,2.43,26.3,0.0922,20.6,129,Dy_accu,21.004
18,350,2.02,20.8,0.0973,16.2,107,Dy_accu,21.005
19,355,1.67,16.3,0.102,12.8,88.7,Dy_accu,21.006
20,360,1.38,12.9,0.107,10.1,73.2,Dy_accu,21.007
21,365,1.13,10.1,0.112,7.93,60.1,Dy_accu,21.007
22,370,0.927,7.99,0.116,6.25,49.2,Dy_accu,21.005
23,375,0.756,6.29,0.12,4.92,40.2,Dy_accu,21.002
24,380,0.616,4.96,0.124,3.87,32.7,Dy_accu,20.998
25,385,0.498,3.9,0.128,3.05,26.4,Dy_accu,20.996
26,390,0.403,3.07,0.131,2.4,21.4,Dy_accu,20.995
27,395,0.325,2.42,0.134,1.89,17.3,Dy_accu,20.995
28,400,0.262,1.91,0.138,1.49,13.9,Dy_accu,20.994
29,405,0.212,1.5,0.141,1.17,11.2,Dy_accu,20.994
30,410,0.17,1.18,0.144,0.925,9.02,Dy_accu,20.995
31,415,0.136,0.932,0.146,0.729,7.23,Dy_accu,20.995
32,420,0.109,0.734,0.149,0.574,5.8,Dy_accu,20.996
33,425,0.087,0.578,0.151,0.452,4.62,Dy_accu,20.997
34,430,0.0695,0.456,0.153,0.356,3.69,Dy_accu,20.996
35,435,0.0555,0.359,0.155,0.281,2.94,Dy_accu,20.997
36,440,0.0443,0.283,0.157,0.221,2.35,Dy_accu,20.997
37,445,0.0353,0.223,0.159,0.174,1.87,Dy_accu,20.997
38,450,0.0278,0.175,0.159,0.137,1.48,Dy_accu,20.998
39,455,0.0223,0.138,0.162,0.108,1.18,Dy_accu,20.998
40,460,0.0176,0.109,0.162,0.0851,0.936,Dy_accu,20.998
41,465,0.0139,0.0857,0.162,0.067,0.739,Dy_accu,20.998
42,470,0.0111,0.0675,0.164,0.0528,0.587,Dy_accu,20.998
43,475,0.00884,0.0531,0.166,0.0416,0.469,Dy_accu,20.998
44,480,0.00683,0.0419,0.163,0.0327,0.363,Dy_accu,20.999
45,485,0.00554,0.033,0.168,0.0258,0.294,Dy_accu,20.997
46,490,0.00425,0.026,0.164,0.0203,0.226,Dy_accu,20.998
47,495,0.00323,0.0205,0.158,0.016,0.171,Dy_accu,20.997
48,500,0.00238,0.0161,0.148,0.0126,0.126,Dy_accu,20.997
49,505,0.0017,0.0127,0.134,0.00993,0.0903,Dy_accu,20.997
50,510,0.00124,0.01,0.124,0.00782,0.0659,Dy_accu,20.996